Workbook

Sheet NPP Sup DDKD
A2: HCM4 – KH BQ tháng ≥20 triệu đang gắn F2/F4
A3: Tổng hợp NPP → Sup → DDKD; không cộng chồng các cấp. Đề xuất nâng lịch F8 theo T+3.
A5: Số KH | B5: 167
A6: BQ tháng nhóm (triệu) | B6: =SUM('F4'!H2:H7) -> 178.92746
A7: BQ tháng HCM4 (triệu) | B7: 124278.9
A8: Đóng góp BQ tháng HCM4 | B8: =B6/B7 -> 0.0014397251
A10: Cấp | B10: NPP | C10: Sup | D10: DDKD | E10: F2 (KH) | F10: F4 (KH) | G10: Tổng KH | H10: Trước RS (KH) | I10: Sau RS (KH) | J10: BQ tháng (triệu) | K10: % BQ HCM4
A11: NPP | B11: Châu Gia Việt | E11: =COUNTIFS('F4'!#REF!,B11,'F4'!F2:F7,"F2") -> #REF! | F11: =COUNTIFS('F4'!#REF!,B11,'F4'!F2:F7,"F4") -> #REF! | G11: =E11+F11 -> #REF! | H11: =COUNTIFS('F4'!#REF!,B11,'F4'!I2:I7,"Trước RS") -> #REF! | I11: =COUNTIFS('F4'!#REF!,B11,'F4'!I2:I7,"Sau RS") -> #REF! | J11: =SUMIFS('F4'!H2:H7,'F4'!#REF!,B11) -> #REF! | K11: =J11/$B$7 -> #REF!
A12: Sup | B12: Châu Gia Việt | C12: Lê Hoàng Nguyên | E12: =COUNTIFS('F4'!#REF!,B12,'F4'!A2:A7,C12,'F4'!F2:F7,"F2") -> #REF! | F12: =COUNTIFS('F4'!#REF!,B12,'F4'!A2:A7,C12,'F4'!F2:F7,"F4") -> #REF! | G12: =E12+F12 -> #REF! | H12: =COUNTIFS('F4'!#REF!,B12,'F4'!A2:A7,C12,'F4'!I2:I7,"Trước RS") -> #REF! | I12: =COUNTIFS('F4'!#REF!,B12,'F4'!A2:A7,C12,'F4'!I2:I7,"Sau RS") -> #REF! | J12: =SUMIFS('F4'!H2:H7,'F4'!#REF!,B12,'F4'!A2:A7,C12) -> #REF! | K12: =J12/$B$7 -> #REF!
A13: DDKD | B13: Châu Gia Việt | C13: Lê Hoàng Nguyên | D13: Lê Hoàng Thanh Bảo | E13: =COUNTIFS('F4'!#REF!,B13,'F4'!A2:A7,C13,'F4'!B2:B7,D13,'F4'!F2:F7,"F2") -> #REF! | F13: =COUNTIFS('F4'!#REF!,B13,'F4'!A2:A7,C13,'F4'!B2:B7,D13,'F4'!F2:F7,"F4") -> #REF! | G13: =E13+F13 -> #REF! | H13: =COUNTIFS('F4'!#REF!,B13,'F4'!A2:A7,C13,'F4'!B2:B7,D13,'F4'!I2:I7,"Trước RS") -> #REF! | I13: =COUNTIFS('F4'!#REF!,B13,'F4'!A2:A7,C13,'F4'!B2:B7,D13,'F4'!I2:I7,"Sau RS") -> #REF! | J13: =SUMIFS('F4'!H2:H7,'F4'!#REF!,B13,'F4'!A2:A7,C13,'F4'!B2:B7,D13) -> #REF! | K13: =J13/$B$7 -> #REF!
A14: DDKD | B14: Châu Gia Việt | C14: Lê Hoàng Nguyên | D14: Mai Thị Bé Diệu | E14: =COUNTIFS('F4'!#REF!,B14,'F4'!A2:A7,C14,'F4'!B2:B7,D14,'F4'!F2:F7,"F2") -> #REF! | F14: =COUNTIFS('F4'!#REF!,B14,'F4'!A2:A7,C14,'F4'!B2:B7,D14,'F4'!F2:F7,"F4") -> #REF! | G14: =E14+F14 -> #REF! | H14: =COUNTIFS('F4'!#REF!,B14,'F4'!A2:A7,C14,'F4'!B2:B7,D14,'F4'!I2:I7,"Trước RS") -> #REF! | I14: =COUNTIFS('F4'!#REF!,B14,'F4'!A2:A7,C14,'F4'!B2:B7,D14,'F4'!I2:I7,"Sau RS") -> #REF! | J14: =SUMIFS('F4'!H2:H7,'F4'!#REF!,B14,'F4'!A2:A7,C14,'F4'!B2:B7,D14) -> #REF! | K14: =J14/$B$7 -> #REF!
A15: DDKD | B15: Châu Gia Việt | C15: Lê Hoàng Nguyên | D15: Phạm Thanh Trường | E15: =COUNTIFS('F4'!#REF!,B15,'F4'!A2:A7,C15,'F4'!B2:B7,D15,'F4'!F2:F7,"F2") -> #REF! | F15: =COUNTIFS('F4'!#REF!,B15,'F4'!A2:A7,C15,'F4'!B2:B7,D15,'F4'!F2:F7,"F4") -> #REF! | G15: =E15+F15 -> #REF! | H15: =COUNTIFS('F4'!#REF!,B15,'F4'!A2:A7,C15,'F4'!B2:B7,D15,'F4'!I2:I7,"Trước RS") -> #REF! | I15: =COUNTIFS('F4'!#REF!,B15,'F4'!A2:A7,C15,'F4'!B2:B7,D15,'F4'!I2:I7,"Sau RS") -> #REF! | J15: =SUMIFS('F4'!H2:H7,'F4'!#REF!,B15,'F4'!A2:A7,C15,'F4'!B2:B7,D15) -> #REF! | K15: =J15/$B$7 -> #REF!
A16: DDKD | B16: Châu Gia Việt | C16: Lê Hoàng Nguyên | D16: Trịnh Văn Minh | E16: =COUNTIFS('F4'!#REF!,B16,'F4'!A2:A7,C16,'F4'!B2:B7,D16,'F4'!F2:F7,"F2") -> #REF! | F16: =COUNTIFS('F4'!#REF!,B16,'F4'!A2:A7,C16,'F4'!B2:B7,D16,'F4'!F2:F7,"F4") -> #REF! | G16: =E16+F16 -> #REF! | H16: =COUNTIFS('F4'!#REF!,B16,'F4'!A2:A7,C16,'F4'!B2:B7,D16,'F4'!I2:I7,"Trước RS") -> #REF! | I16: =COUNTIFS('F4'!#REF!,B16,'F4'!A2:A7,C16,'F4'!B2:B7,D16,'F4'!I2:I7,"Sau RS") -> #REF! | J16: =SUMIFS('F4'!H2:H7,'F4'!#REF!,B16,'F4'!A2:A7,C16,'F4'!B2:B7,D16) -> #REF! | K16: =J16/$B$7 -> #REF!
A17: DDKD | B17: Châu Gia Việt | C17: Lê Hoàng Nguyên | D17: Đinh Công Truyền | E17: =COUNTIFS('F4'!#REF!,B17,'F4'!A2:A7,C17,'F4'!B2:B7,D17,'F4'!F2:F7,"F2") -> #REF! | F17: =COUNTIFS('F4'!#REF!,B17,'F4'!A2:A7,C17,'F4'!B2:B7,D17,'F4'!F2:F7,"F4") -> #REF! | G17: =E17+F17 -> #REF! | H17: =COUNTIFS('F4'!#REF!,B17,'F4'!A2:A7,C17,'F4'!B2:B7,D17,'F4'!I2:I7,"Trước RS") -> #REF! | I17: =COUNTIFS('F4'!#REF!,B17,'F4'!A2:A7,C17,'F4'!B2:B7,D17,'F4'!I2:I7,"Sau RS") -> #REF! | J17: =SUMIFS('F4'!H2:H7,'F4'!#REF!,B17,'F4'!A2:A7,C17,'F4'!B2:B7,D17) -> #REF! | K17: =J17/$B$7 -> #REF!
A18: Sup | B18: Châu Gia Việt | C18: Phan Long Hoàng | E18: =COUNTIFS('F4'!#REF!,B18,'F4'!A2:A7,C18,'F4'!F2:F7,"F2") -> #REF! | F18: =COUNTIFS('F4'!#REF!,B18,'F4'!A2:A7,C18,'F4'!F2:F7,"F4") -> #REF! | G18: =E18+F18 -> #REF! | H18: =COUNTIFS('F4'!#REF!,B18,'F4'!A2:A7,C18,'F4'!I2:I7,"Trước RS") -> #REF! | I18: =COUNTIFS('F4'!#REF!,B18,'F4'!A2:A7,C18,'F4'!I2:I7,"Sau RS") -> #REF! | J18: =SUMIFS('F4'!H2:H7,'F4'!#REF!,B18,'F4'!A2:A7,C18) -> #REF! | K18: =J18/$B$7 -> #REF!
A19: DDKD | B19: Châu Gia Việt | C19: Phan Long Hoàng | D19: Huỳnh Thu Thuyền | E19: =COUNTIFS('F4'!#REF!,B19,'F4'!A2:A7,C19,'F4'!B2:B7,D19,'F4'!F2:F7,"F2") -> #REF! | F19: =COUNTIFS('F4'!#REF!,B19,'F4'!A2:A7,C19,'F4'!B2:B7,D19,'F4'!F2:F7,"F4") -> #REF! | G19: =E19+F19 -> #REF! | H19: =COUNTIFS('F4'!#REF!,B19,'F4'!A2:A7,C19,'F4'!B2:B7,D19,'F4'!I2:I7,"Trước RS") -> #REF! | I19: =COUNTIFS('F4'!#REF!,B19,'F4'!A2:A7,C19,'F4'!B2:B7,D19,'F4'!I2:I7,"Sau RS") -> #REF! | J19: =SUMIFS('F4'!H2:H7,'F4'!#REF!,B19,'F4'!A2:A7,C19,'F4'!B2:B7,D19) -> #REF! | K19: =J19/$B$7 -> #REF!
A20: DDKD | B20: Châu Gia Việt | C20: Phan Long Hoàng | D20: Lê Hùng Đức | E20: =COUNTIFS('F4'!#REF!,B20,'F4'!A2:A7,C20,'F4'!B2:B7,D20,'F4'!F2:F7,"F2") -> #REF! | F20: =COUNTIFS('F4'!#REF!,B20,'F4'!A2:A7,C20,'F4'!B2:B7,D20,'F4'!F2:F7,"F4") -> #REF! | G20: =E20+F20 -> #REF! | H20: =COUNTIFS('F4'!#REF!,B20,'F4'!A2:A7,C20,'F4'!B2:B7,D20,'F4'!I2:I7,"Trước RS") -> #REF! | I20: =COUNTIFS('F4'!#REF!,B20,'F4'!A2:A7,C20,'F4'!B2:B7,D20,'F4'!I2:I7,"Sau RS") -> #REF! | J20: =SUMIFS('F4'!H2:H7,'F4'!#REF!,B20,'F4'!A2:A7,C20,'F4'!B2:B7,D20) -> #REF! | K20: =J20/$B$7 -> #REF!
A21: DDKD | B21: Châu Gia Việt | C21: Phan Long Hoàng | D21: Nguyễn Phước Tài | E21: =COUNTIFS('F4'!#REF!,B21,'F4'!A2:A7,C21,'F4'!B2:B7,D21,'F4'!F2:F7,"F2") -> #REF! | F21: =COUNTIFS('F4'!#REF!,B21,'F4'!A2:A7,C21,'F4'!B2:B7,D21,'F4'!F2:F7,"F4") -> #REF! | G21: =E21+F21 -> #REF! | H21: =COUNTIFS('F4'!#REF!,B21,'F4'!A2:A7,C21,'F4'!B2:B7,D21,'F4'!I2:I7,"Trước RS") -> #REF! | I21: =COUNTIFS('F4'!#REF!,B21,'F4'!A2:A7,C21,'F4'!B2:B7,D21,'F4'!I2:I7,"Sau RS") -> #REF! | J21: =SUMIFS('F4'!H2:H7,'F4'!#REF!,B21,'F4'!A2:A7,C21,'F4'!B2:B7,D21) -> #REF! | K21: =J21/$B$7 -> #REF!
A22: DDKD | B22: Châu Gia Việt | C22: Phan Long Hoàng | D22: Nguyễn Thị Kim Xuyến | E22: =COUNTIFS('F4'!#REF!,B22,'F4'!A2:A7,C22,'F4'!B2:B7,D22,'F4'!F2:F7,"F2") -> #REF! | F22: =COUNTIFS('F4'!#REF!,B22,'F4'!A2:A7,C22,'F4'!B2:B7,D22,'F4'!F2:F7,"F4") -> #REF! | G22: =E22+F22 -> #REF! | H22: =COUNTIFS('F4'!#REF!,B22,'F4'!A2:A7,C22,'F4'!B2:B7,D22,'F4'!I2:I7,"Trước RS") -> #REF! | I22: =COUNTIFS('F4'!#REF!,B22,'F4'!A2:A7,C22,'F4'!B2:B7,D22,'F4'!I2:I7,"Sau RS") -> #REF! | J22: =SUMIFS('F4'!H2:H7,'F4'!#REF!,B22,'F4'!A2:A7,C22,'F4'!B2:B7,D22) -> #REF! | K22: =J22/$B$7 -> #REF!
A23: DDKD | B23: Châu Gia Việt | C23: Phan Long Hoàng | D23: Nguyễn Văn Sinh | E23: =COUNTIFS('F4'!#REF!,B23,'F4'!A2:A7,C23,'F4'!B2:B7,D23,'F4'!F2:F7,"F2") -> #REF! | F23: =COUNTIFS('F4'!#REF!,B23,'F4'!A2:A7,C23,'F4'!B2:B7,D23,'F4'!F2:F7,"F4") -> #REF! | G23: =E23+F23 -> #REF! | H23: =COUNTIFS('F4'!#REF!,B23,'F4'!A2:A7,C23,'F4'!B2:B7,D23,'F4'!I2:I7,"Trước RS") -> #REF! | I23: =COUNTIFS('F4'!#REF!,B23,'F4'!A2:A7,C23,'F4'!B2:B7,D23,'F4'!I2:I7,"Sau RS") -> #REF! | J23: =SUMIFS('F4'!H2:H7,'F4'!#REF!,B23,'F4'!A2:A7,C23,'F4'!B2:B7,D23) -> #REF! | K23: =J23/$B$7 -> #REF!
A24: DDKD | B24: Châu Gia Việt | C24: Phan Long Hoàng | D24: Đỗ Hồng Phúc | E24: =COUNTIFS('F4'!#REF!,B24,'F4'!A2:A7,C24,'F4'!B2:B7,D24,'F4'!F2:F7,"F2") -> #REF! | F24: =COUNTIFS('F4'!#REF!,B24,'F4'!A2:A7,C24,'F4'!B2:B7,D24,'F4'!F2:F7,"F4") -> #REF! | G24: =E24+F24 -> #REF! | H24: =COUNTIFS('F4'!#REF!,B24,'F4'!A2:A7,C24,'F4'!B2:B7,D24,'F4'!I2:I7,"Trước RS") -> #REF! | I24: =COUNTIFS('F4'!#REF!,B24,'F4'!A2:A7,C24,'F4'!B2:B7,D24,'F4'!I2:I7,"Sau RS") -> #REF! | J24: =SUMIFS('F4'!H2:H7,'F4'!#REF!,B24,'F4'!A2:A7,C24,'F4'!B2:B7,D24) -> #REF! | K24: =J24/$B$7 -> #REF!
A25: NPP | B25: Minh Phát Thành | E25: =COUNTIFS('F4'!#REF!,B25,'F4'!F2:F7,"F2") -> #REF! | F25: =COUNTIFS('F4'!#REF!,B25,'F4'!F2:F7,"F4") -> #REF! | G25: =E25+F25 -> #REF! | H25: =COUNTIFS('F4'!#REF!,B25,'F4'!I2:I7,"Trước RS") -> #REF! | I25: =COUNTIFS('F4'!#REF!,B25,'F4'!I2:I7,"Sau RS") -> #REF! | J25: =SUMIFS('F4'!H2:H7,'F4'!#REF!,B25) -> #REF! | K25: =J25/$B$7 -> #REF!
A26: Sup | B26: Minh Phát Thành | C26: Lê Thanh Thông | E26: =COUNTIFS('F4'!#REF!,B26,'F4'!A2:A7,C26,'F4'!F2:F7,"F2") -> #REF! | F26: =COUNTIFS('F4'!#REF!,B26,'F4'!A2:A7,C26,'F4'!F2:F7,"F4") -> #REF! | G26: =E26+F26 -> #REF! | H26: =COUNTIFS('F4'!#REF!,B26,'F4'!A2:A7,C26,'F4'!I2:I7,"Trước RS") -> #REF! | I26: =COUNTIFS('F4'!#REF!,B26,'F4'!A2:A7,C26,'F4'!I2:I7,"Sau RS") -> #REF! | J26: =SUMIFS('F4'!H2:H7,'F4'!#REF!,B26,'F4'!A2:A7,C26) -> #REF! | K26: =J26/$B$7 -> #REF!
A27: DDKD | B27: Minh Phát Thành | C27: Lê Thanh Thông | D27: Danh Kiệt | E27: =COUNTIFS('F4'!#REF!,B27,'F4'!A2:A7,C27,'F4'!B2:B7,D27,'F4'!F2:F7,"F2") -> #REF! | F27: =COUNTIFS('F4'!#REF!,B27,'F4'!A2:A7,C27,'F4'!B2:B7,D27,'F4'!F2:F7,"F4") -> #REF! | G27: =E27+F27 -> #REF! | H27: =COUNTIFS('F4'!#REF!,B27,'F4'!A2:A7,C27,'F4'!B2:B7,D27,'F4'!I2:I7,"Trước RS") -> #REF! | I27: =COUNTIFS('F4'!#REF!,B27,'F4'!A2:A7,C27,'F4'!B2:B7,D27,'F4'!I2:I7,"Sau RS") -> #REF! | J27: =SUMIFS('F4'!H2:H7,'F4'!#REF!,B27,'F4'!A2:A7,C27,'F4'!B2:B7,D27) -> #REF! | K27: =J27/$B$7 -> #REF!
A28: DDKD | B28: Minh Phát Thành | C28: Lê Thanh Thông | D28: Lê Võ Nghĩa | E28: =COUNTIFS('F4'!#REF!,B28,'F4'!A2:A7,C28,'F4'!B2:B7,D28,'F4'!F2:F7,"F2") -> #REF! | F28: =COUNTIFS('F4'!#REF!,B28,'F4'!A2:A7,C28,'F4'!B2:B7,D28,'F4'!F2:F7,"F4") -> #REF! | G28: =E28+F28 -> #REF! | H28: =COUNTIFS('F4'!#REF!,B28,'F4'!A2:A7,C28,'F4'!B2:B7,D28,'F4'!I2:I7,"Trước RS") -> #REF! | I28: =COUNTIFS('F4'!#REF!,B28,'F4'!A2:A7,C28,'F4'!B2:B7,D28,'F4'!I2:I7,"Sau RS") -> #REF! | J28: =SUMIFS('F4'!H2:H7,'F4'!#REF!,B28,'F4'!A2:A7,C28,'F4'!B2:B7,D28) -> #REF! | K28: =J28/$B$7 -> #REF!
A29: DDKD | B29: Minh Phát Thành | C29: Lê Thanh Thông | D29: Lưu Thị Hạnh Nguyên | E29: =COUNTIFS('F4'!#REF!,B29,'F4'!A2:A7,C29,'F4'!B2:B7,D29,'F4'!F2:F7,"F2") -> #REF! | F29: =COUNTIFS('F4'!#REF!,B29,'F4'!A2:A7,C29,'F4'!B2:B7,D29,'F4'!F2:F7,"F4") -> #REF! | G29: =E29+F29 -> #REF! | H29: =COUNTIFS('F4'!#REF!,B29,'F4'!A2:A7,C29,'F4'!B2:B7,D29,'F4'!I2:I7,"Trước RS") -> #REF! | I29: =COUNTIFS('F4'!#REF!,B29,'F4'!A2:A7,C29,'F4'!B2:B7,D29,'F4'!I2:I7,"Sau RS") -> #REF! | J29: =SUMIFS('F4'!H2:H7,'F4'!#REF!,B29,'F4'!A2:A7,C29,'F4'!B2:B7,D29) -> #REF! | K29: =J29/$B$7 -> #REF!
A30: DDKD | B30: Minh Phát Thành | C30: Lê Thanh Thông | D30: Nguyễn Bảo Duy | E30: =COUNTIFS('F4'!#REF!,B30,'F4'!A2:A7,C30,'F4'!B2:B7,D30,'F4'!F2:F7,"F2") -> #REF! | F30: =COUNTIFS('F4'!#REF!,B30,'F4'!A2:A7,C30,'F4'!B2:B7,D30,'F4'!F2:F7,"F4") -> #REF! | G30: =E30+F30 -> #REF! | H30: =COUNTIFS('F4'!#REF!,B30,'F4'!A2:A7,C30,'F4'!B2:B7,D30,'F4'!I2:I7,"Trước RS") -> #REF! | I30: =COUNTIFS('F4'!#REF!,B30,'F4'!A2:A7,C30,'F4'!B2:B7,D30,'F4'!I2:I7,"Sau RS") -> #REF! | J30: =SUMIFS('F4'!H2:H7,'F4'!#REF!,B30,'F4'!A2:A7,C30,'F4'!B2:B7,D30) -> #REF! | K30: =J30/$B$7 -> #REF!
A31: DDKD | B31: Minh Phát Thành | C31: Lê Thanh Thông | D31: Nguyễn Thái Dương | E31: =COUNTIFS('F4'!#REF!,B31,'F4'!A2:A7,C31,'F4'!B2:B7,D31,'F4'!F2:F7,"F2") -> #REF! | F31: =COUNTIFS('F4'!#REF!,B31,'F4'!A2:A7,C31,'F4'!B2:B7,D31,'F4'!F2:F7,"F4") -> #REF! | G31: =E31+F31 -> #REF! | H31: =COUNTIFS('F4'!#REF!,B31,'F4'!A2:A7,C31,'F4'!B2:B7,D31,'F4'!I2:I7,"Trước RS") -> #REF! | I31: =COUNTIFS('F4'!#REF!,B31,'F4'!A2:A7,C31,'F4'!B2:B7,D31,'F4'!I2:I7,"Sau RS") -> #REF! | J31: =SUMIFS('F4'!H2:H7,'F4'!#REF!,B31,'F4'!A2:A7,C31,'F4'!B2:B7,D31) -> #REF! | K31: =J31/$B$7 -> #REF!
A32: DDKD | B32: Minh Phát Thành | C32: Lê Thanh Thông | D32: Nguyễn Thị Thanh Nhàn | E32: =COUNTIFS('F4'!#REF!,B32,'F4'!A2:A7,C32,'F4'!B2:B7,D32,'F4'!F2:F7,"F2") -> #REF! | F32: =COUNTIFS('F4'!#REF!,B32,'F4'!A2:A7,C32,'F4'!B2:B7,D32,'F4'!F2:F7,"F4") -> #REF! | G32: =E32+F32 -> #REF! | H32: =COUNTIFS('F4'!#REF!,B32,'F4'!A2:A7,C32,'F4'!B2:B7,D32,'F4'!I2:I7,"Trước RS") -> #REF! | I32: =COUNTIFS('F4'!#REF!,B32,'F4'!A2:A7,C32,'F4'!B2:B7,D32,'F4'!I2:I7,"Sau RS") -> #REF! | J32: =SUMIFS('F4'!H2:H7,'F4'!#REF!,B32,'F4'!A2:A7,C32,'F4'!B2:B7,D32) -> #REF! | K32: =J32/$B$7 -> #REF!
A33: DDKD | B33: Minh Phát Thành | C33: Lê Thanh Thông | D33: Nguyễn Thị Thanh Thúy | E33: =COUNTIFS('F4'!#REF!,B33,'F4'!A2:A7,C33,'F4'!B2:B7,D33,'F4'!F2:F7,"F2") -> #REF! | F33: =COUNTIFS('F4'!#REF!,B33,'F4'!A2:A7,C33,'F4'!B2:B7,D33,'F4'!F2:F7,"F4") -> #REF! | G33: =E33+F33 -> #REF! | H33: =COUNTIFS('F4'!#REF!,B33,'F4'!A2:A7,C33,'F4'!B2:B7,D33,'F4'!I2:I7,"Trước RS") -> #REF! | I33: =COUNTIFS('F4'!#REF!,B33,'F4'!A2:A7,C33,'F4'!B2:B7,D33,'F4'!I2:I7,"Sau RS") -> #REF! | J33: =SUMIFS('F4'!H2:H7,'F4'!#REF!,B33,'F4'!A2:A7,C33,'F4'!B2:B7,D33) -> #REF! | K33: =J33/$B$7 -> #REF!
A34: DDKD | B34: Minh Phát Thành | C34: Lê Thanh Thông | D34: Nguyễn Thị Ánh Trinh | E34: =COUNTIFS('F4'!#REF!,B34,'F4'!A2:A7,C34,'F4'!B2:B7,D34,'F4'!F2:F7,"F2") -> #REF! | F34: =COUNTIFS('F4'!#REF!,B34,'F4'!A2:A7,C34,'F4'!B2:B7,D34,'F4'!F2:F7,"F4") -> #REF! | G34: =E34+F34 -> #REF! | H34: =COUNTIFS('F4'!#REF!,B34,'F4'!A2:A7,C34,'F4'!B2:B7,D34,'F4'!I2:I7,"Trước RS") -> #REF! | I34: =COUNTIFS('F4'!#REF!,B34,'F4'!A2:A7,C34,'F4'!B2:B7,D34,'F4'!I2:I7,"Sau RS") -> #REF! | J34: =SUMIFS('F4'!H2:H7,'F4'!#REF!,B34,'F4'!A2:A7,C34,'F4'!B2:B7,D34) -> #REF! | K34: =J34/$B$7 -> #REF!
A35: DDKD | B35: Minh Phát Thành | C35: Lê Thanh Thông | D35: Nguyễn Văn Vương | E35: =COUNTIFS('F4'!#REF!,B35,'F4'!A2:A7,C35,'F4'!B2:B7,D35,'F4'!F2:F7,"F2") -> #REF! | F35: =COUNTIFS('F4'!#REF!,B35,'F4'!A2:A7,C35,'F4'!B2:B7,D35,'F4'!F2:F7,"F4") -> #REF! | G35: =E35+F35 -> #REF! | H35: =COUNTIFS('F4'!#REF!,B35,'F4'!A2:A7,C35,'F4'!B2:B7,D35,'F4'!I2:I7,"Trước RS") -> #REF! | I35: =COUNTIFS('F4'!#REF!,B35,'F4'!A2:A7,C35,'F4'!B2:B7,D35,'F4'!I2:I7,"Sau RS") -> #REF! | J35: =SUMIFS('F4'!H2:H7,'F4'!#REF!,B35,'F4'!A2:A7,C35,'F4'!B2:B7,D35) -> #REF! | K35: =J35/$B$7 -> #REF!
A36: DDKD | B36: Minh Phát Thành | C36: Lê Thanh Thông | D36: Trương Hoàng Việt | E36: =COUNTIFS('F4'!#REF!,B36,'F4'!A2:A7,C36,'F4'!B2:B7,D36,'F4'!F2:F7,"F2") -> #REF! | F36: =COUNTIFS('F4'!#REF!,B36,'F4'!A2:A7,C36,'F4'!B2:B7,D36,'F4'!F2:F7,"F4") -> #REF! | G36: =E36+F36 -> #REF! | H36: =COUNTIFS('F4'!#REF!,B36,'F4'!A2:A7,C36,'F4'!B2:B7,D36,'F4'!I2:I7,"Trước RS") -> #REF! | I36: =COUNTIFS('F4'!#REF!,B36,'F4'!A2:A7,C36,'F4'!B2:B7,D36,'F4'!I2:I7,"Sau RS") -> #REF! | J36: =SUMIFS('F4'!H2:H7,'F4'!#REF!,B36,'F4'!A2:A7,C36,'F4'!B2:B7,D36) -> #REF! | K36: =J36/$B$7 -> #REF!
A37: Sup | B37: Minh Phát Thành | C37: Nguyễn Thị Tường Vy | E37: =COUNTIFS('F4'!#REF!,B37,'F4'!A2:A7,C37,'F4'!F2:F7,"F2") -> #REF! | F37: =COUNTIFS('F4'!#REF!,B37,'F4'!A2:A7,C37,'F4'!F2:F7,"F4") -> #REF! | G37: =E37+F37 -> #REF! | H37: =COUNTIFS('F4'!#REF!,B37,'F4'!A2:A7,C37,'F4'!I2:I7,"Trước RS") -> #REF! | I37: =COUNTIFS('F4'!#REF!,B37,'F4'!A2:A7,C37,'F4'!I2:I7,"Sau RS") -> #REF! | J37: =SUMIFS('F4'!H2:H7,'F4'!#REF!,B37,'F4'!A2:A7,C37) -> #REF! | K37: =J37/$B$7 -> #REF!
A38: DDKD | B38: Minh Phát Thành | C38: Nguyễn Thị Tường Vy | D38: Huỳnh Hữu Chính | E38: =COUNTIFS('F4'!#REF!,B38,'F4'!A2:A7,C38,'F4'!B2:B7,D38,'F4'!F2:F7,"F2") -> #REF! | F38: =COUNTIFS('F4'!#REF!,B38,'F4'!A2:A7,C38,'F4'!B2:B7,D38,'F4'!F2:F7,"F4") -> #REF! | G38: =E38+F38 -> #REF! | H38: =COUNTIFS('F4'!#REF!,B38,'F4'!A2:A7,C38,'F4'!B2:B7,D38,'F4'!I2:I7,"Trước RS") -> #REF! | I38: =COUNTIFS('F4'!#REF!,B38,'F4'!A2:A7,C38,'F4'!B2:B7,D38,'F4'!I2:I7,"Sau RS") -> #REF! | J38: =SUMIFS('F4'!H2:H7,'F4'!#REF!,B38,'F4'!A2:A7,C38,'F4'!B2:B7,D38) -> #REF! | K38: =J38/$B$7 -> #REF!
A39: DDKD | B39: Minh Phát Thành | C39: Nguyễn Thị Tường Vy | D39: Lê Tấn Cường | E39: =COUNTIFS('F4'!#REF!,B39,'F4'!A2:A7,C39,'F4'!B2:B7,D39,'F4'!F2:F7,"F2") -> #REF! | F39: =COUNTIFS('F4'!#REF!,B39,'F4'!A2:A7,C39,'F4'!B2:B7,D39,'F4'!F2:F7,"F4") -> #REF! | G39: =E39+F39 -> #REF! | H39: =COUNTIFS('F4'!#REF!,B39,'F4'!A2:A7,C39,'F4'!B2:B7,D39,'F4'!I2:I7,"Trước RS") -> #REF! | I39: =COUNTIFS('F4'!#REF!,B39,'F4'!A2:A7,C39,'F4'!B2:B7,D39,'F4'!I2:I7,"Sau RS") -> #REF! | J39: =SUMIFS('F4'!H2:H7,'F4'!#REF!,B39,'F4'!A2:A7,C39,'F4'!B2:B7,D39) -> #REF! | K39: =J39/$B$7 -> #REF!
A40: DDKD | B40: Minh Phát Thành | C40: Nguyễn Thị Tường Vy | D40: Lý Quốc Mẫn | E40: =COUNTIFS('F4'!#REF!,B40,'F4'!A2:A7,C40,'F4'!B2:B7,D40,'F4'!F2:F7,"F2") -> #REF! | F40: =COUNTIFS('F4'!#REF!,B40,'F4'!A2:A7,C40,'F4'!B2:B7,D40,'F4'!F2:F7,"F4") -> #REF! | G40: =E40+F40 -> #REF! | H40: =COUNTIFS('F4'!#REF!,B40,'F4'!A2:A7,C40,'F4'!B2:B7,D40,'F4'!I2:I7,"Trước RS") -> #REF! | I40: =COUNTIFS('F4'!#REF!,B40,'F4'!A2:A7,C40,'F4'!B2:B7,D40,'F4'!I2:I7,"Sau RS") -> #REF! | J40: =SUMIFS('F4'!H2:H7,'F4'!#REF!,B40,'F4'!A2:A7,C40,'F4'!B2:B7,D40) -> #REF! | K40: =J40/$B$7 -> #REF!
A41: DDKD | B41: Minh Phát Thành | C41: Nguyễn Thị Tường Vy | D41: Nguyễn Tấn Trung | E41: =COUNTIFS('F4'!#REF!,B41,'F4'!A2:A7,C41,'F4'!B2:B7,D41,'F4'!F2:F7,"F2") -> #REF! | F41: =COUNTIFS('F4'!#REF!,B41,'F4'!A2:A7,C41,'F4'!B2:B7,D41,'F4'!F2:F7,"F4") -> #REF! | G41: =E41+F41 -> #REF! | H41: =COUNTIFS('F4'!#REF!,B41,'F4'!A2:A7,C41,'F4'!B2:B7,D41,'F4'!I2:I7,"Trước RS") -> #REF! | I41: =COUNTIFS('F4'!#REF!,B41,'F4'!A2:A7,C41,'F4'!B2:B7,D41,'F4'!I2:I7,"Sau RS") -> #REF! | J41: =SUMIFS('F4'!H2:H7,'F4'!#REF!,B41,'F4'!A2:A7,C41,'F4'!B2:B7,D41) -> #REF! | K41: =J41/$B$7 -> #REF!
A42: DDKD | B42: Minh Phát Thành | C42: Nguyễn Thị Tường Vy | D42: Nguyễn Tấn Tài | E42: =COUNTIFS('F4'!#REF!,B42,'F4'!A2:A7,C42,'F4'!B2:B7,D42,'F4'!F2:F7,"F2") -> #REF! | F42: =COUNTIFS('F4'!#REF!,B42,'F4'!A2:A7,C42,'F4'!B2:B7,D42,'F4'!F2:F7,"F4") -> #REF! | G42: =E42+F42 -> #REF! | H42: =COUNTIFS('F4'!#REF!,B42,'F4'!A2:A7,C42,'F4'!B2:B7,D42,'F4'!I2:I7,"Trước RS") -> #REF! | I42: =COUNTIFS('F4'!#REF!,B42,'F4'!A2:A7,C42,'F4'!B2:B7,D42,'F4'!I2:I7,"Sau RS") -> #REF! | J42: =SUMIFS('F4'!H2:H7,'F4'!#REF!,B42,'F4'!A2:A7,C42,'F4'!B2:B7,D42) -> #REF! | K42: =J42/$B$7 -> #REF!
A43: DDKD | B43: Minh Phát Thành | C43: Nguyễn Thị Tường Vy | D43: Nguyễn Tấn Tươi | E43: =COUNTIFS('F4'!#REF!,B43,'F4'!A2:A7,C43,'F4'!B2:B7,D43,'F4'!F2:F7,"F2") -> #REF! | F43: =COUNTIFS('F4'!#REF!,B43,'F4'!A2:A7,C43,'F4'!B2:B7,D43,'F4'!F2:F7,"F4") -> #REF! | G43: =E43+F43 -> #REF! | H43: =COUNTIFS('F4'!#REF!,B43,'F4'!A2:A7,C43,'F4'!B2:B7,D43,'F4'!I2:I7,"Trước RS") -> #REF! | I43: =COUNTIFS('F4'!#REF!,B43,'F4'!A2:A7,C43,'F4'!B2:B7,D43,'F4'!I2:I7,"Sau RS") -> #REF! | J43: =SUMIFS('F4'!H2:H7,'F4'!#REF!,B43,'F4'!A2:A7,C43,'F4'!B2:B7,D43) -> #REF! | K43: =J43/$B$7 -> #REF!
...

Sheet F4
A1: Sup | B1: DDKD | C1: POS | D1: Mã KH | E1: Tên KH | F1: Tần suất hiện tại | G1: Sales 3M (triệu) | H1: BQ tháng (triệu) | I1: Nhóm RS | J1: Created_date | K1: Kênh | L1: VIP MCH | M1: NGÀY VT KO TÍNH TRÁI TUYẾN | N1: Tuần hiện tại | O1: Ngày VT bổ sung T+3 | P1: Tần suất đề xuất | Q1: Phường/Xã | R1: Địa chỉ | S1: Tuần đề xuất
A2: Lê Minh Chiến | B2: Lê Ngọc Bảo | C2: SM-FM-10KF3761.06 | D2: 3046451 | E2: Công Ty Stella | F2: F4 | G2: 77.864 | H2: =G2/3 -> 25.954667 | I2: Trước RS | J2: 2024-07-23 | K2: Kênh Off Premise | L2: VIP5 | M2: 47 | N2: Both | O2: T4 | P2: F8 | Q2: P. An Phú (TP. Hồ Chí Minh) | R2: 40, Đại Lộ Tự Do | S2: Both
A3: Lê Minh Chiến | B3: Lê Văn Minh Thuận | C3: SM-FM-10KF3761.16 | D3: 3073841 | E3: Tạp Hóa Yến Nhung | F3: F4 | G3: 110.4418 | H3: =G3/3 -> 36.813933 | I3: Trước RS | J3: 2024-10-04 | K3: Kênh Off Premise | L3: VIP5 | M3: 25 | N3: Both | O3: T2 | P3: F8 | Q3: P. Thuận Giao | R3: Kế Nhà 38a, Đường Na 12 | S3: Both
A4: Lê Minh Chiến | B4: Nguyễn Chí Nguyên | C4: SM-FM-10KF3761.13 | D4: 5906 | E4: Thái Ngọc | F4: F4 | G4: 60.18954 | H4: =G4/3 -> 20.06318 | I4: Trước RS | J4: 2014-09-03 | K4: Kênh Off Premise | L4: VIP3 | M4: 47 | N4: Both | O4: T4 | P4: F8 | Q4: P. Bình Hòa | R4: 3/20, Nguyễn Du | S4: Both
A5: Lê Minh Chiến | B5: Nguyễn Lê Quốc Anh | C5: SM-FM-10KF3761.14 | D5: 2017721 | E5: Anh Đào | F5: F4 | G5: 89.601476 | H5: =G5/3 -> 29.867159 | I5: Trước RS | J5: 2015-04-20 | K5: Kênh Off Premise | L5: VIP5 | M5: 47 | N5: Both | O5: T7 | P5: F8 | Q5: P. Bình Hòa | R5: H4, Chợ khu dân cư Minh Tuấn | S5: Both
A6: Lê Minh Chiến | B6: Phùng Minh Trí | C6: SM-FM-10KF3761.09 | D6: 348563 | E6: Quỳnh Như | F6: F4 | G6: 89.4054 | H6: =G6/3 -> 29.8018 | I6: Trước RS | J6: 2015-01-10 | K6: Kênh Off Premise | L6: VIP5 | M6: 25 | N6: Both | O6: T5 | P6: F8 | Q6: P. An Phú (TP. Hồ Chí Minh) | R6: 27A11, Khu Phố 3, Khu Dân Cư An Phú | S6: Both
A7: Lê Minh Chiến | B7: Đoàn Thị Hoàng Ngọc | C7: SM-FM-10KF3761.22 | D7: 3041126 | E7: ÁNH DƯƠNG | F7: F4 | G7: 109.28016 | H7: =G7/3 -> 36.42672 | I7: Trước RS | J7: 2024-07-09 | K7: Kênh Off Premise | L7: LẺ | M7: 25 | N7: Both | O7: T2 | P7: F8 | Q7: P. Thuận Giao | R7: 24/11 ĐT 743, KP Bình Phú | S7: Both

Sheet F2
A1: Sup | B1: DDKD | C1: POS | D1: Mã KH | E1: Tên KH | F1: Tần suất hiện tại | G1: Sales 3M (triệu) | H1: BQ tháng (triệu) | I1: Nhóm RS | J1: Created_date | K1: Kênh | L1: VIP MCH | M1: NGÀY VT KO TÍNH TRÁI TUYẾN | N1: Tuần hiện tại | O1: Ngày VT bổ sung T+3 | P1: TẦN SUẤT KO TÍNH TRÁI TUYẾN | Q1: Phường/Xã | R1: Địa chỉ | S1: Tuần đề xuất
A2: Lê Minh Chiến | B2: Lê Ngọc Bảo | C2: SM-FM-10KF3761.06 | D2: 999257698 | E2: CHỊ LÝ | F2: F2 | G2: 8.681456 | H2: =G2/3 -> 2.8938187 | I2: Trước RS | J2: 2025-10-31 | K2: Kênh Off Premise | L2: LẺ | M2: 7 | N2: Odd Week | O2: T4 | P2: F8 | Q2: P. An Phú (TP. Hồ Chí Minh) | R2: Ô07, D9 | S2: Both
A3: Lê Minh Chiến | B3: Lê Thiện An | C3: SM-FM-10KF3761.05 | D3: 99997541 | E3: Nước Ép Trái Cây | F3: F2 | G3: 7.5208 | H3: =G3/3 -> 2.5069333 | I3: Trước RS | J3: 2025-08-25 | K3: Kênh On Premise | L3: LẺ | M3: 3 | N3: Even Week | O3: T6 | P3: F8 | Q3: P. Lái Thiêu | R3: 141/5, Phan Đình Phùng | S3: Both
A4: Lê Minh Chiến | B4: Lê Thiện An | C4: SM-FM-10KF3761.05 | D4: 3062283 | E4: Cà Phê Thu Thảo | F4: F2 | G4: 6.0668 | H4: =G4/3 -> 2.0222667 | I4: Trước RS | J4: 2024-08-28 | K4: Kênh On Premise | L4: LẺ | M4: 6 | N4: Odd Week | O4: T3 | P4: F8 | Q4: P. Lái Thiêu | R4: 32B, Cách Mạng Tháng 8 | S4: Both
A5: Lê Minh Chiến | B5: Lê Thị Kim Thoa | C5: SM-FM-10KF3761.18 | D5: 999752303 | E5: Tạp Hóa Cô Sương | F5: F2 | G5: 58.185912 | H5: =G5/3 -> 19.395304 | I5: Trước RS | J5: 2026-06-12 | K5: Kênh Off Premise | L5: LẺ | M5: 5 | N5: Odd Week | O5: T2 | P5: F8 | Q5: P. Thuận Giao | R5: Đối Diện Lẩu Bò Ngã 4 Hòa Lân, Thủ Khoa Huân | S5: Both
A6: Lê Minh Chiến | B6: Lê Thị Kim Thoa | C6: SM-FM-10KF3761.18 | D6: 999227317 | E6: Cô Minh | F6: F2 | G6: 17.261 | H6: =G6/3 -> 5.7536667 | I6: Trước RS | J6: 2025-10-16 | K6: Kênh Off Premise | L6: LẺ | M6: 5 | N6: Even Week | O6: T2 | P6: F8 | Q6: P. Thuận Giao | R6: 34, Thuận Giao 33 | S6: Both
A7: Lê Minh Chiến | B7: Lê Thị Kim Thoa | C7: SM-FM-10KF3761.18 | D7: 999752031 | E7: Nhà Trọ Cô Hương Chú Phúc | F7: F2 | G7: 14.6507 | H7: =G7/3 -> 4.8835667 | I7: Trước RS | J7: 2026-06-10 | K7: Kênh Off Premise | L7: LẺ | M7: 4 | N7: Even Week | O7: T7 | P7: F8 | Q7: P. Thuận Giao | R7: 4/5, 22/12 | S7: Both
A8: Lê Minh Chiến | B8: Lê Thị Kim Thoa | C8: SM-FM-10KF3761.18 | D8: 999750579 | E8: Trà Sữa Cô Phượng | F8: F2 | G8: 10.87792 | H8: =G8/3 -> 3.6259733 | I8: Trước RS | J8: 2026-05-29 | K8: Kênh On Premise | L8: LẺ | M8: 5 | N8: Odd Week | O8: T2 | P8: F8 | Q8: P. Thuận Giao | R8: 1A/9, Thuận Giao 16 | S8: Both
A9: Lê Minh Chiến | B9: Lê Thị Kim Thoa | C9: SM-FM-10KF3761.18 | D9: 99924117 | E9: Chị Giang | F9: F2 | G9: 10.4116 | H9: =G9/3 -> 3.4705333 | I9: Trước RS | J9: 2025-07-09 | K9: Kênh On Premise | L9: LẺ | M9: 7 | N9: Even Week | O9: T4 | P9: F8 | Q9: P. Thuận Giao | R9: 02, KCN. Việt Hương | S9: Both
A10: Lê Minh Chiến | B10: Lê Thị Kim Thoa | C10: SM-FM-10KF3761.18 | D10: 999375182 | E10: Hưng Vân | F10: F2 | G10: 10.325952 | H10: =G10/3 -> 3.441984 | I10: Trước RS | J10: 2026-01-05 | K10: Kênh Off Premise | L10: LẺ | M10: 5 | N10: Odd Week | O10: T2 | P10: F8 | Q10: P. Thuận Giao | R10: 44, Hẻm QL13 | S10: Both
A11: Lê Minh Chiến | B11: Lê Thị Kim Thoa | C11: SM-FM-10KF3761.18 | D11: 999751648 | E11: Cafe Giải Khát Chợ Đêm Hòa Lân | F11: F2 | G11: 10.174 | H11: =G11/3 -> 3.3913333 | I11: Trước RS | J11: 2026-06-08 | K11: Kênh On Premise | L11: LẺ | M11: 4 | N11: Even Week | O11: T7 | P11: F8 | Q11: P. Thuận Giao | R11: chợ đêm hòa lân, chợ đêm hòa lân | S11: Both
A12: Lê Minh Chiến | B12: Lê Thị Kim Thoa | C12: SM-FM-10KF3761.18 | D12: 999161097 | E12: Tạp Hóa Cô Bình | F12: F2 | G12: 8.497432 | H12: =G12/3 -> 2.8324773 | I12: Trước RS | J12: 2025-09-23 | K12: Kênh Off Premise | L12: LẺ | M12: 5 | N12: Even Week | O12: T2 | P12: F8 | Q12: P. Thuận Giao | R12: 4, Hòa Lân 1 | S12: Both
A13: Lê Minh Chiến | B13: Lê Thị Kim Thoa | C13: SM-FM-10KF3761.18 | D13: 999754422 | E13: Tạp Hóa Trung Liên | F13: F2 | G13: 8.362 | H13: =G13/3 -> 2.7873333 | I13: Sau RS | J13: 2026-07-02 | K13: Kênh Off Premise | L13: LẺ | M13: 4 | N13: Odd Week | O13: T7 | P13: F8 | Q13: P. Thuận Giao | R13: Cạnh đường Thuận Giao 26, Đại Lộ Bình Dương | S13: Both
... A107: Lê Minh Chiến | B107: Đoàn Thị Hoàng Ngọc | C107: SM-FM-10KF3761.22 | D107: 999749812 | E107: Tạp Hóa Chị Vân | F107: F2 | G107: 8.6264 | H107: =G107/3 -> 2.8754667 | I107: Trước RS | J107: 2026-05-26 | K107: Kênh Off Premise | L107: LẺ | M107: 3 | N107: Odd Week | O107: T6 | P107: F8 | Q107: P. Thuận Giao | R107: 02, Bình Chuẩn 15 | S107: Both
